Traceback (most recent call last):
  File "/Users/tiffany/opt/miniconda3/lib/python3.9/site-packages/jupyter_cache/executors/utils.py", line 51, in single_nb_execution
    executenb(
  File "/Users/tiffany/opt/miniconda3/lib/python3.9/site-packages/nbclient/client.py", line 1085, in execute
    return NotebookClient(nb=nb, resources=resources, km=km, **kwargs).execute()
  File "/Users/tiffany/opt/miniconda3/lib/python3.9/site-packages/nbclient/util.py", line 84, in wrapped
    return just_run(coro(*args, **kwargs))
  File "/Users/tiffany/opt/miniconda3/lib/python3.9/site-packages/nbclient/util.py", line 62, in just_run
    return loop.run_until_complete(coro)
  File "/Users/tiffany/opt/miniconda3/lib/python3.9/asyncio/base_events.py", line 642, in run_until_complete
    return future.result()
  File "/Users/tiffany/opt/miniconda3/lib/python3.9/site-packages/nbclient/client.py", line 551, in async_execute
    await self.async_execute_cell(
  File "/Users/tiffany/opt/miniconda3/lib/python3.9/site-packages/nbclient/client.py", line 846, in async_execute_cell
    self._check_raise_for_error(cell, exec_reply)
  File "/Users/tiffany/opt/miniconda3/lib/python3.9/site-packages/nbclient/client.py", line 748, in _check_raise_for_error
    raise CellExecutionError.from_cell_and_msg(cell, exec_reply_content)
nbclient.exceptions.CellExecutionError: An error occurred while executing the following cell:
------------------
library(tidyverse)
library(gapminder)

gapminder |>
  filter(country == "Canada", year == 1952)
------------------

Error in library(gapminder): there is no package called ‘gapminder’
Traceback:

1. library(gapminder)
ERROR: Error in library(gapminder): there is no package called ‘gapminder’


